Workbook
Name TAB_P_SEQ: 'Tabelas de Referência'!$B$7:$C$11
Name TAB_P_IRR: 'Tabelas de Referência'!$B$15:$C$19
Name TAB_K: 'Tabelas de Referência'!$B$23:$C$27
Name TAB_MO: 'Tabelas de Referência'!$B$31:$C$33
Name TAB_CA: 'Tabelas de Referência'!$B$37:$C$39
Name TAB_MG: 'Tabelas de Referência'!$B$43:$C$45
Name TAB_PH: 'Tabelas de Referência'!$B$49:$C$53
Name TAB_V: 'Tabelas de Referência'!$B$57:$C$61
Name TAB_M: 'Tabelas de Referência'!$B$65:$C$68
Name TAB_ZN: 'Tabelas de Referência'!$B$72:$C$74
Name TAB_CU: 'Tabelas de Referência'!$B$78:$C$80
Name TAB_MN: 'Tabelas de Referência'!$B$84:$C$86
Name TAB_FE: 'Tabelas de Referência'!$B$90:$C$92
Name TAB_B: 'Tabelas de Referência'!$B$96:$C$98
Name TAB_MOL: 'Tabelas de Referência'!$B$102:$C$104
Name TAB_V2_CULTURA: Calagem!$J$16:$K$22
Name TAB_UF_CERRADO: Calagem!$J$25:$K$51
Name TAB_CULTURAS: 'BD Culturas'!$B$6:$T$12
Name TAB_EFICIENCIA: 'BD Culturas'!$B$20:$D$22
Name TAB_FATOR_CLASSE: 'BD Culturas'!$B$25:$C$30
Name TAB_MICRO_DOSE: 'BD Culturas'!$A$33:$D$47
Name TAB_FERT: 'BD Fertilizantes'!$B$6:$Q$36

Sheet Início
B2: AE ADUBAÇÃO — Recomendação Técnica de Calagem, Gessagem e Fertilização
B3: Sistema de apoio à decisão para correção e adubação de solos — Soja, Milho, Sorgo, Feijão, Cana-de-açúcar e Pastagens (Panicum e Brachiaria)
B5: Como usar esta planilha
B6: 1. Preencha a aba "Dados de Entrada" — identificação da área, cultura, meta de produtividade e análise de solo completa.
B7: 2. A aba "Interpretação" classifica automaticamente cada nutriente (Muito baixo a Muito alto).
B8: 3. As abas "Calagem" e "Gessagem" calculam a correção do solo por múltiplos métodos e indicam a recomendação final.
B9: 4. As abas "Soja" e "Milho" (motor completo) ou "Outras Culturas" (Sorgo, Feijão, Cana, Panicum, Brachiaria) calculam a adubação de N, P, K, S, Ca, Mg e micronutrientes.
B10: 5. A aba "Mistura de Fertilizantes" converte a necessidade de nutrientes em produtos comerciais, dose por hectare, total da área e custo estimado.
B11: 6. A aba "Resumo" reúne o diagnóstico, o balanço de nutrientes e os gráficos para impressão/apresentação.
B12: 7. Consulte "Manual Técnico" para as fórmulas, premissas e limitações, e "Referências" para a bibliografia de cada recomendação.
B14: Mapa das abas
B15: Aba | C15: Conteúdo
B16: Manual Técnico | C16: Metodologia, equações, premissas, limitações e nível de confiança de cada recomendação.
B17: Dados de Entrada | C17: Único local de digitação de dados da área e da análise de solo. Células amarelas = editáveis.
B18: Tabelas de Referência | C18: Classes de interpretação de fertilidade (Boletim 100/IAC, Cerrado/SBCS) — editável para atualização.
B19: Interpretação | C19: Classificação automática de cada nutriente e diagnóstico de limitações do solo.
B20: Calagem | C20: 3 métodos de cálculo da necessidade de calcário + escolha automática e PRNT.
B21: Gessagem | C21: Critério técnico e dose de gesso agrícola.
B22: BD Culturas | C22: Extração, exportação, eficiência e curvas de resposta por cultura e faixa de produtividade.
B23: Soja | C23: Motor completo de recomendação de N-P-K-S-Ca-Mg-micros para soja.
B24: Milho | C24: Motor completo de recomendação de N-P-K-S-Ca-Mg-micros para milho.
B25: Outras Culturas | C25: Recomendação de manutenção/reposição para Sorgo, Feijão, Cana, Panicum e Brachiaria.
B26: BD Fertilizantes | C26: Composição garantida e preço de referência dos fertilizantes comerciais (editável).
... B29: Referências | C29: Bibliografia utilizada em cada metodologia.
B31: Legenda de cores
C32: Célula de entrada — o usuário digita ou escolhe em lista suspensa
C33: Célula de fórmula (cálculo automático) — não recomendado editar
C34: Resultado final / recomendação
C35: Alerta / atenção técnica
B37: IMPORTANTE: nenhuma célula está protegida — todas as fórmulas são abertas e auditáveis. As recomendações combinam análise de solo, textura, CTC, matéria orgânica, histórico da área, cultura, produtividade esperada, exportação de nutrientes e eficiência dos fertilizantes. Elas não substituem a responsabilidade técnica de um(a) Engenheiro(a) Agrônomo(a) para a emissão de receituário agronômico. Fase 1 desta planilha: motor completo para Soja e Milho; demais culturas em nível de manutenção/reposição (ver Manual Técnico, seção de limitações).

Sheet Manual Técnico
B1: MANUAL TÉCNICO — Metodologia, Equações, Premissas e Limitações
B3: 1. Objetivo e Escopo (Fase 1)
B4: Esta planilha é um sistema de apoio à decisão para calagem, gessagem e adubação de solos agrícolas brasileiros. A Fase 1 (esta versão) entrega motor de cálculo completo e integrado para Soja e Milho (N, P, K, S, Ca, Mg e micronutrientes, com ajuste por análise de solo, textura e produtividade meta), e um módulo simplificado de manutenção/reposição por exportação de nutrientes para Sorgo, Feijão, Cana-de-açúcar, Pastagem Panicum e Pastagem Brachiaria. Fases futuras podem aprofundar essas 5 culturas com o mesmo rigor de Soja/Milho, adicionar interface VBA/Solver para otimização de mistura por custo mínimo, e publicar versões em Google Sheets/Power BI.
B6: 2. Fluxo de Cálculo
B7: Dados de Entrada (análise de solo + manejo) → conversão de unidades → Interpretação (classes de fertilidade) → Calagem (3 métodos) e Gessagem (critério técnico) → Adubação por cultura (exportação/eficiência/ajuste por classe) → Mistura de Fertilizantes (produtos, doses, custo) → Resumo (diagnóstico, balanço, gráficos). Cada etapa referencia a anterior por fórmula - alterar um dado de entrada recalcula toda a cadeia automaticamente.
B9: 3. Conversão de Unidades
B10: K, Ca, Mg, Al: 1 mmolc/dm³ = 0,1 cmolc/dm³. Conversão para mg/dm³ usa a massa equivalente (massa atômica ÷ carga): K = 39,1; Ca = 20,0; Mg = 12,15; Al = 9,0 mg/dm³ por mmolc/dm³. H+Al: cmolc/dm³ × 10 = mmolc/dm³. Matéria Orgânica: g/kg tratado como numericamente igual a g/dm³ (convenção de densidade ≈ 1, usual em laboratórios tropicais); % × 10 = g/dm³. P, S e micronutrientes (Zn, Cu, Mn, Fe, B, Mo): mg/dm³ tratado como numericamente equivalente a ppm.
B12: 4. Índices de Fertilidade (SBCS)
B13: SB (Soma de Bases) = K⁺ + Ca²⁺ + Mg²⁺ + Na⁺ (mmolc/dm³). CTC efetiva (t) = SB + Al³⁺. CTC a pH 7,0 (T) = SB + H+Al. V% = SB/T × 100. m% = Al³⁺/CTC efetiva × 100. Convenção padrão da Sociedade Brasileira de Ciência do Solo (SBCS), consistente com Raij et al. (Boletim 100, IAC) e Sousa & Lobato (Embrapa Cerrados).
B15: 5. Calagem — 3 Métodos (todos calculados; ver aba Calagem)
B16: (a) Método da saturação por bases: NC (t/ha) = CTC pH7 (mmolc/dm³) × (V2 - V1) / (10 × PRNT). Fonte: Raij, van B.; Cantarella, H.; Quaggio, J.A.; Furlani, A.M.C. Recomendações de Adubação e Calagem para o Estado de São Paulo. Boletim Técnico 100, 2ª ed. IAC, 1997. Confiança: Alta (fórmula confirmada).
B17: (b) Método de neutralização do Alumínio (Kamprath): NC (t/ha) = Al³⁺ (cmolc/dm³) × 2 × (100/PRNT). Fonte: Kamprath, E.J. Exchangeable aluminum as a criterion for liming leached mineral soils. Soil Science Society of America Proceedings, v.34, 1970. Confiança: Média (fator 2 é o valor consagrado na prática brasileira; a derivação original relata variação entre 1,5 e 2,4 conforme o solo).
... B47: Nenhuma célula está protegida ou oculta (exceto pequenas células auxiliares de suporte a listas, identificadas por fonte branca). Toda recomendação final pode ser rastreada até a análise de solo de origem, seguindo as fórmulas de aba em aba. Sempre que existir mais de uma metodologia aplicável (como em Calagem), todas são calculadas e exibidas lado a lado, com fonte, justificativa técnica e nível de confiança da recomendação final.

Sheet Dados de Entrada
B1: DADOS DE ENTRADA — Área, Manejo e Análise de Solo
B3: 1. Identificação da Área e Manejo
B4: Fazenda / Talhão | C4: Talhão 1
B5: Município | C5: Rio Verde
B6: Estado (UF) | C6: GO
B7: Área (ha) | C7: 100
B8: Cultura | C8: Soja
B9: Produtividade esperada (meta) | C9: 60
B10: Unidade da produtividade | C10: sc/ha (60 kg)
B11: Sistema de produção | C11: Sequeiro
B12: Sistema de plantio | C12: Plantio direto
B13: Anos sob plantio direto consolidado | C13: 5
B14: Histórico de calagem/gessagem na área | C14: Sim, regular
B16: 2. Dados Físicos do Solo
B17: Profundidade de amostragem (cm) | C17: 0-20
B18: Teor de argila (%) | C18: 35
B19: Classe textural (calculada) | C19: =IF(C18="","",IF(C18<15,"Arenoso (< 15% argila)",IF(C18<=35,"Textura média (15-35% argila)","Argiloso (> 35% argila)")))
B20: P-remanescente (mg/L)
B22: 3. Análise Química do Solo — insira o valor, escolha a unidade do laudo
B23: Determinação | C23: Valor do laudo | D23: Unidade do laudo | E23: Valor padronizado | F23: Unidade padrão | G23: Observação
B24: pH (CaCl₂ 0,01 mol/L) | C24: 5.2 | D24: - | E24: =IF(C24="","",C24) | F24: - | G24: Se sua análise for em água, subtraia cerca de 0,5 a 0,7 unidade para equivaler ao CaCl₂ (Raij et al., Boletim 100).
B25: Matéria Orgânica | C25: 28 | D25: g/dm³ | E25: =IF(C25="","",IF(D25="g/dm³",C25,IF(D25="g/kg",C25,C25*10))) | F25: g/dm³ | G25: Conversão % → g/dm³ e g/kg → g/dm³ assume densidade do solo ≈ 1 (convenção usual de laboratórios tropicais).
B26: Fósforo (P) | C26: 12 | D26: mg/dm³ | E26: =IF(C26="","",C26) | F26: Resina | G26: Informe o extrator ao lado (afeta a tabela de interpretação).
B27: Potássio (K) | C27: 2.5 | D27: mmolc/dm³ | E27: =IF(C27="","",IF(D27="mmolc/dm³",C27,IF(D27="cmolc/dm³",C27*10,IF(D27="mg/dm³",C27/39.1,C27)))) | F27: mmolc/dm³ | G27: 1 mmolc/dm³ K⁺ = 39,1 mg/dm³ (massa atômica 39,1 g/mol, carga 1).
B28: Cálcio (Ca²⁺) | C28: 25 | D28: mmolc/dm³ | E28: =IF(C28="","",IF(D28="mmolc/dm³",C28,IF(D28="cmolc/dm³",C28*10,IF(D28="mg/dm³",C28/20,C28)))) | F28: mmolc/dm³ | G28: 1 mmolc/dm³ Ca²⁺ = 20 mg/dm³ (massa atômica 40 g/mol ÷ carga 2).
B29: Magnésio (Mg²⁺) | C29: 10 | D29: mmolc/dm³ | E29: =IF(C29="","",IF(D29="mmolc/dm³",C29,IF(D29="cmolc/dm³",C29*10,IF(D29="mg/dm³",C29/12.15,C29)))) | F29: mmolc/dm³ | G29: 1 mmolc/dm³ Mg²⁺ = 12,15 mg/dm³ (massa atômica 24,3 g/mol ÷ carga 2).
B30: Alumínio (Al³⁺) | C30: 2 | D30: mmolc/dm³ | E30: =IF(C30="","",IF(D30="mmolc/dm³",C30,IF(D30="cmolc/dm³",C30*10,IF(D30="mg/dm³",C30/9,C30)))) | F30: mmolc/dm³ | G30: 1 mmolc/dm³ Al³⁺ = 9 mg/dm³ (massa atômica 27 g/mol ÷ carga 3).
B31: Acidez potencial (H+Al) | C31: 35 | D31: mmolc/dm³ | E31: =IF(C31="","",IF(D31="cmolc/dm³",C31*10,C31)) | F31: mmolc/dm³ | G31: Obtida por SMP ou solução tampão (Ca-acetato pH 7,0).
B32: Enxofre (S-SO₄²⁻) | C32: 8 | D32: mg/dm³ | E32: =IF(C32="","",C32) | F32: mg/dm³ | G32: Extrator fosfato de cálcio 0,01 mol/L (Ca(H2PO4)2).
B33: Boro (B) | C33: 0.25 | D33: mg/dm³ | E33: =IF(C33="","",C33) | F33: mg/dm³ | G33: Água quente.
B34: Cobre (Cu) | C34: 1.5 | D34: mg/dm³ | E34: =IF(C34="","",C34) | F34: mg/dm³ | G34: DTPA ou Mehlich-1.
B35: Ferro (Fe) | C35: 25 | D35: mg/dm³ | E35: =IF(C35="","",C35) | F35: mg/dm³ | G35: DTPA ou Mehlich-1.
B36: Manganês (Mn) | C36: 8 | D36: mg/dm³ | E36: =IF(C36="","",C36) | F36: mg/dm³ | G36: DTPA ou Mehlich-1.
B37: Zinco (Zn) | C37: 1 | D37: mg/dm³ | E37: =IF(C37="","",C37) | F37: mg/dm³ | G37: DTPA ou Mehlich-1.
B38: Molibdênio (Mo) | C38: 0.1 | D38: mg/dm³ | E38: =IF(C38="","",C38) | F38: mg/dm³ | G38: Extração por oxalato de amônio (pouco realizado rotineiramente).
B39: Sódio (Na) | C39: 5 | D39: mg/dm³ | E39: =IF(C39="","",C39) | F39: mg/dm³ | G39: Relevante em áreas irrigadas / risco de sodicidade.
B41: 4. Índices Calculados (SBCS) — não editar, calculados a partir da análise acima
B42: Soma de Bases (SB = K+Ca+Mg+Na), mmolc/dm³ | C42: =E27+E28+E29+E39/23
B43: CTC efetiva (t = SB + Al), mmolc/dm³ | C43: =C42+E30
B44: CTC a pH 7,0 (T = SB + H+Al), mmolc/dm³ | C44: =C42+E31
...

Sheet Tabelas de Referência
B1: TABELAS DE REFERÊNCIA — Classes de Interpretação de Fertilidade (editável)
B3: Estas tabelas alimentam a aba "Interpretação" por busca aproximada (limite inferior de cada classe). Podem ser editadas para refletir um boletim regional mais atualizado — a planilha recalcula automaticamente. Fonte e nível de confiança de cada bloco estão registrados ao lado.
B5: Fósforo (mg/dm³) — Sistema Cerrado, Sequeiro | E5: Fonte: Sousa, D.M.G.; Lobato, E. Cerrado: Correção do Solo e Adubação. Embrapa Cerrados, 2004. | Confiança: Alta
B6: Limite inferior | C6: Classe
B7: 0 | C7: Muito baixo
B8: 5 | C8: Baixo
B9: 8 | C9: Médio
B10: 14 | C10: Adequado
B11: 20 | C11: Alto
B13: Fósforo (mg/dm³) — Sistema Cerrado, Irrigado | E13: Fonte: Sousa, D.M.G.; Lobato, E. Cerrado: Correção do Solo e Adubação. Embrapa Cerrados, 2004. | Confiança: Alta
B14: Limite inferior | C14: Classe
B15: 0 | C15: Muito baixo
B16: 8 | C16: Baixo
B17: 14 | C17: Médio
B18: 20 | C18: Adequado
B19: 35 | C19: Alto
B21: Potássio trocável (mmolc/dm³) | E21: Fonte: Raij et al., Boletim Técnico 100, IAC. | Confiança: Alta (faixas) / Média (sem estratificação por CTC do original)
B22: Limite inferior | C22: Classe
B23: 0 | C23: Muito baixo
B24: 0.7 | C24: Baixo
B25: 1.5 | C25: Médio
B26: 3 | C26: Alto
B27: 6 | C27: Muito alto
B29: Matéria Orgânica (g/dm³) | E29: Fonte: Síntese didática consolidada na literatura agronômica brasileira (não reverificada diretamente contra o Boletim 100 nesta versão). | Confiança: Média
B30: Limite inferior | C30: Classe
B31: 0 | C31: Baixo
B32: 15 | C32: Médio
B33: 30 | C33: Alto
B35: Cálcio trocável (mmolc/dm³) | E35: Fonte: Faixas de referência de uso corrente na literatura agronômica brasileira para cálcio trocável (não reverificadas diretamente contra o Boletim 100 nesta versão). | Confiança: Baixa-Média
B36: Limite inferior | C36: Classe
B37: 0 | C37: Baixo
B38: 4 | C38: Médio
B39: 7 | C39: Alto
B41: Magnésio trocável (mmolc/dm³) | E41: Fonte: Faixas de referência de uso corrente na literatura agronômica brasileira para magnésio trocável (não reverificadas diretamente contra o Boletim 100 nesta versão). | Confiança: Baixa-Média
B42: Limite inferior | C42: Classe
B43: 0 | C43: Baixo
B44: 4 | C44: Médio
B45: 8 | C45: Alto
B47: pH (CaCl₂) | E47: Fonte: Faixa de referência de uso amplo na prática agronômica brasileira (pH em CaCl₂); o alvo técnico de correção é definido pelo V% e não pelo pH isolado. | Confiança: Média
B48: Limite inferior | C48: Classe
...

Sheet Interpretação
B1: INTERPRETAÇÃO AUTOMÁTICA DA ANÁLISE DE SOLO
B3: Parâmetro | C3: Valor padronizado | D3: Unidade | E3: Classificação | F3: Diagnóstico / Ação sugerida
B4: pH (CaCl₂) | C4: ='Dados de Entrada'!E24 | D4: - | E4: =VLOOKUP(C4,TAB_PH,2,TRUE) | F4: =IF(OR(E4="Muito baixo",E4="Baixo"),"Prioridade de correção/construção de fertilidade",IF(E4="Médio","Adequado - manter e monitorar",IF(OR(E4="Alto",E4="Muito alto"),"Sem prioridade - risco de excesso/custo desnecessário se adubar",IF(E4="Adequado","Adequado - manter e monitorar","-"))))
B5: Matéria Orgânica | C5: ='Dados de Entrada'!E25 | D5: g/dm³ | E5: =VLOOKUP(C5,TAB_MO,2,TRUE) | F5: =IF(OR(E5="Muito baixo",E5="Baixo"),"Prioridade de correção/construção de fertilidade",IF(E5="Médio","Adequado - manter e monitorar",IF(OR(E5="Alto",E5="Muito alto"),"Sem prioridade - risco de excesso/custo desnecessário se adubar",IF(E5="Adequado","Adequado - manter e monitorar","-"))))
B6: Fósforo (P) | C6: ='Dados de Entrada'!E26 | D6: mg/dm³ | E6: =VLOOKUP(C6,IF('Dados de Entrada'!C11="Irrigado",TAB_P_IRR,TAB_P_SEQ),2,TRUE) | F6: =IF(OR(E6="Muito baixo",E6="Baixo"),"Prioridade de correção/construção de fertilidade",IF(E6="Médio","Adequado - manter e monitorar",IF(OR(E6="Alto",E6="Muito alto"),"Sem prioridade - risco de excesso/custo desnecessário se adubar",IF(E6="Adequado","Adequado - manter e monitorar","-"))))
B7: Potássio (K) | C7: ='Dados de Entrada'!E27 | D7: mmolc/dm³ | E7: =VLOOKUP(C7,TAB_K,2,TRUE) | F7: =IF(OR(E7="Muito baixo",E7="Baixo"),"Prioridade de correção/construção de fertilidade",IF(E7="Médio","Adequado - manter e monitorar",IF(OR(E7="Alto",E7="Muito alto"),"Sem prioridade - risco de excesso/custo desnecessário se adubar",IF(E7="Adequado","Adequado - manter e monitorar","-"))))
B8: Cálcio (Ca) | C8: ='Dados de Entrada'!E28 | D8: mmolc/dm³ | E8: =VLOOKUP(C8,TAB_CA,2,TRUE) | F8: =IF(OR(E8="Muito baixo",E8="Baixo"),"Prioridade de correção/construção de fertilidade",IF(E8="Médio","Adequado - manter e monitorar",IF(OR(E8="Alto",E8="Muito alto"),"Sem prioridade - risco de excesso/custo desnecessário se adubar",IF(E8="Adequado","Adequado - manter e monitorar","-"))))
B9: Magnésio (Mg) | C9: ='Dados de Entrada'!E29 | D9: mmolc/dm³ | E9: =VLOOKUP(C9,TAB_MG,2,TRUE) | F9: =IF(OR(E9="Muito baixo",E9="Baixo"),"Prioridade de correção/construção de fertilidade",IF(E9="Médio","Adequado - manter e monitorar",IF(OR(E9="Alto",E9="Muito alto"),"Sem prioridade - risco de excesso/custo desnecessário se adubar",IF(E9="Adequado","Adequado - manter e monitorar","-"))))
B10: Saturação por Bases (V%) | C10: ='Dados de Entrada'!C45 | D10: % | E10: =VLOOKUP(C10,TAB_V,2,TRUE) | F10: =IF(OR(E10="Muito baixo",E10="Baixo"),"Prioridade de correção/construção de fertilidade",IF(E10="Médio","Adequado - manter e monitorar",IF(OR(E10="Alto",E10="Muito alto"),"Sem prioridade - risco de excesso/custo desnecessário se adubar",IF(E10="Adequado","Adequado - manter e monitorar","-"))))
B11: Saturação por Alumínio (m%) | C11: ='Dados de Entrada'!C46 | D11: % | E11: =VLOOKUP(C11,TAB_M,2,TRUE) | F11: =IF(OR(E11="Alto",E11="Muito alto"),"Prioridade de correção (calagem/gessagem)",IF(E11="Médio","Atenção - monitorar risco de toxidez",IF(OR(E11="Baixo",E11="Muito baixo"),"Sem restrição - condição favorável","-")))
B12: Enxofre (S-SO₄) | C12: ='Dados de Entrada'!E32 | D12: mg/dm³ | E12: =IF(C12<5,"Baixo",IF(C12<=10,"Médio","Alto")) | F12: =IF(OR(E12="Muito baixo",E12="Baixo"),"Prioridade de correção/construção de fertilidade",IF(E12="Médio","Adequado - manter e monitorar",IF(OR(E12="Alto",E12="Muito alto"),"Sem prioridade - risco de excesso/custo desnecessário se adubar",IF(E12="Adequado","Adequado - manter e monitorar","-"))))
B13: Zinco (Zn) | C13: ='Dados de Entrada'!E37 | D13: mg/dm³ | E13: =VLOOKUP(C13,TAB_ZN,2,TRUE) | F13: =IF(OR(E13="Muito baixo",E13="Baixo"),"Prioridade de correção/construção de fertilidade",IF(E13="Médio","Adequado - manter e monitorar",IF(OR(E13="Alto",E13="Muito alto"),"Sem prioridade - risco de excesso/custo desnecessário se adubar",IF(E13="Adequado","Adequado - manter e monitorar","-"))))
B14: Cobre (Cu) | C14: ='Dados de Entrada'!E34 | D14: mg/dm³ | E14: =VLOOKUP(C14,TAB_CU,2,TRUE) | F14: =IF(OR(E14="Muito baixo",E14="Baixo"),"Prioridade de correção/construção de fertilidade",IF(E14="Médio","Adequado - manter e monitorar",IF(OR(E14="Alto",E14="Muito alto"),"Sem prioridade - risco de excesso/custo desnecessário se adubar",IF(E14="Adequado","Adequado - manter e monitorar","-"))))
B15: Manganês (Mn) | C15: ='Dados de Entrada'!E36 | D15: mg/dm³ | E15: =VLOOKUP(C15,TAB_MN,2,TRUE) | F15: =IF(OR(E15="Muito baixo",E15="Baixo"),"Prioridade de correção/construção de fertilidade",IF(E15="Médio","Adequado - manter e monitorar",IF(OR(E15="Alto",E15="Muito alto"),"Sem prioridade - risco de excesso/custo desnecessário se adubar",IF(E15="Adequado","Adequado - manter e monitorar","-"))))
B16: Ferro (Fe) | C16: ='Dados de Entrada'!E35 | D16: mg/dm³ | E16: =VLOOKUP(C16,TAB_FE,2,TRUE) | F16: =IF(OR(E16="Muito baixo",E16="Baixo"),"Prioridade de correção/construção de fertilidade",IF(E16="Médio","Adequado - manter e monitorar",IF(OR(E16="Alto",E16="Muito alto"),"Sem prioridade - risco de excesso/custo desnecessário se adubar",IF(E16="Adequado","Adequado - manter e monitorar","-"))))
B17: Boro (B) | C17: ='Dados de Entrada'!E33 | D17: mg/dm³ | E17: =VLOOKUP(C17,TAB_B,2,TRUE) | F17: =IF(OR(E17="Muito baixo",E17="Baixo"),"Prioridade de correção/construção de fertilidade",IF(E17="Médio","Adequado - manter e monitorar",IF(OR(E17="Alto",E17="Muito alto"),"Sem prioridade - risco de excesso/custo desnecessário se adubar",IF(E17="Adequado","Adequado - manter e monitorar","-"))))
B18: Molibdênio (Mo) | C18: ='Dados de Entrada'!E38 | D18: mg/dm³ | E18: =VLOOKUP(C18,TAB_MOL,2,TRUE) | F18: =IF(OR(E18="Muito baixo",E18="Baixo"),"Prioridade de correção/construção de fertilidade",IF(E18="Médio","Adequado - manter e monitorar",IF(OR(E18="Alto",E18="Muito alto"),"Sem prioridade - risco de excesso/custo desnecessário se adubar",IF(E18="Adequado","Adequado - manter e monitorar","-"))))
B20: Diagnóstico Geral — Limitações do Solo
B21: Nutrientes/atributos em nível Muito baixo ou Baixo (prioridade de correção):
B22: =IF(COUNTIF(H22:H36,"?*")=0,"Nenhuma limitação identificada - solo em nível adequado a alto nos parâmetros avaliados",_xlfn.TEXTJOIN(", ",TRUE,H22:H36)) | H22: =IF(OR(E4="Muito baixo",E4="Baixo"),"pH","")
H23: =IF(OR(E5="Muito baixo",E5="Baixo"),"Matéria Orgânica","")
H24: =IF(OR(E6="Muito baixo",E6="Baixo"),"Fósforo","")
H25: =IF(OR(E7="Muito baixo",E7="Baixo"),"Potássio","")
H26: =IF(OR(E8="Muito baixo",E8="Baixo"),"Cálcio","")
H27: =IF(OR(E9="Muito baixo",E9="Baixo"),"Magnésio","")
H28: =IF(OR(E10="Muito baixo",E10="Baixo"),"V%","")
H29: =IF(OR(E11="Alto",E11="Muito alto"),"m% (Al)","")
H30: =IF(OR(E12="Muito baixo",E12="Baixo"),"Enxofre","")
H31: =IF(OR(E13="Muito baixo",E13="Baixo"),"Zinco","")
H32: =IF(OR(E14="Muito baixo",E14="Baixo"),"Cobre","")
H33: =IF(OR(E15="Muito baixo",E15="Baixo"),"Manganês","")
H34: =IF(OR(E16="Muito baixo",E16="Baixo"),"Ferro","")
H35: =IF(OR(E17="Muito baixo",E17="Baixo"),"Boro","")
H36: =IF(OR(E18="Muito baixo",E18="Baixo"),"Molibdênio","")

Sheet Calagem
B1: CALAGEM — Necessidade de Calcário (3 métodos + escolha técnica)
B3: 1. Parâmetros de entrada (vinculados à aba Dados de Entrada)
B4: CTC a pH 7,0 - T (mmolc/dm³) | C4: ='Dados de Entrada'!C44
B5: Saturação por Bases atual - V1 (%) | C5: ='Dados de Entrada'!C45
B6: Alumínio trocável - Al³⁺ (mmolc/dm³) | C6: ='Dados de Entrada'!E30
B7: Cálcio (Ca²⁺, mmolc/dm³) | C7: ='Dados de Entrada'!E28
B8: Magnésio (Mg²⁺, mmolc/dm³) | C8: ='Dados de Entrada'!E29
B9: Teor de argila (%) | C9: ='Dados de Entrada'!C18
B10: Estado (UF) | C10: ='Dados de Entrada'!C6
B11: Cultura | C11: ='Dados de Entrada'!C8
B12: PRNT do calcário disponível (%) | C12: 80
B13: V2 desejado - override manual (%) [deixe em branco para usar o valor técnico por cultura]
B15: V2 sugerido pela cultura (técnico) | C15: =IFERROR(INDEX(TAB_V2_CULTURA,MATCH(C11,INDEX(TAB_V2_CULTURA,0,1),0),2),70) | J15: Cultura | K15: V2 alvo (%)
B16: V2 adotado no cálculo | C16: =IF(C13="",C15,C13) | J16: Soja | K16: 70
B17: Estado é predominantemente Cerrado? | C17: =IFERROR(VLOOKUP(C10,TAB_UF_CERRADO,2,FALSE),"Não") | J17: Milho | K17: 70
J18: Sorgo | K18: 60
B19: 2. Resultado por método (todos calculados; consulte fonte e confiança) | J19: Feijão | K19: 70
B20: Método | C20: NC bruta a PRNT=100% (t/ha) | D20: PRNT considerado (%) | E20: NC corrigida pelo PRNT (t/ha) | F20: Confiança | J20: Cana-de-açúcar | K20: 60
B21: Método da saturação por bases | C21: =MAX(0,(C4*(C16-C5))/10) | D21: =C12 | E21: =C21*(100/D21) | F21: Alta | J21: Pastagem Panicum | K21: 55
B22: Método de neutralização do Alumínio tóxico (Kamprath) | C22: =(C6/10)*2 | D22: =C12 | E22: =C22*(100/D22) | F22: Média | J22: Pastagem Brachiaria | K22: 50
B23: Método da neutralização do Al³⁺ + elevação de Ca²⁺ e Mg²⁺ (Cerrado) | C23: =(C6/10)*2+MAX(0,2-((C7+C8)/10)) | D23: =C12 | E23: =C23*(100/D23) | F23: Alta
J24: UF | K24: Bioma predominante Cerrado?
B25: 3. Escolha automática e recomendação final | J25: AC | K25: Não
B26: Método recomendado | C26: =IF(C17="Sim","Método da neutralização do Al³⁺ + elevação de Ca²⁺ e Mg²⁺ (Cerrado)","Método da saturação por bases") | J26: AL | K26: Não
B27: NC final corrigida pelo PRNT (t/ha) | C27: =IF(C17="Sim",E23,E21) | J27: AP | K27: Não
B28: Quantidade total para a área (t) | C28: =C27*'Dados de Entrada'!C7 | J28: AM | K28: Não
B29: Parcelamento sugerido | C29: =IF(C27>5,"Aplicar em 2 vezes (metade agora incorporada, metade na safra seguinte) - dose elevada",IF(C27=0,"Sem necessidade de calagem","Aplicação única, incorporada")) | J29: BA | K29: Sim
B30: Justificativa técnica | C30: =IF(C17="Sim","Estado de Cerrado típico: prioriza-se o método de neutralização do Al³⁺ e elevação de Ca+Mg (Sousa & Lobato, 2004), adequado a Latossolos/Oxissolos com CTC baixa e Al tóxico.","Fora do Cerrado típico: prioriza-se o método da saturação por bases (Raij et al., Boletim 100), tradicionalmente usado em SP/MG/ES para culturas anuais.") | J30: CE | K30: Não
J31: DF | K31: Sim
J32: ES | K32: Não
J33: GO | K33: Sim
B34: Nível de confiança da recomendação final | C34: =IF(C17="Sim","Alta (fórmula e critério de aplicação confirmados - Sousa & Lobato, 2004)","Alta (fórmula confirmada - Raij et al., Boletim 100, 1997)") | J34: MA | K34: Sim
J35: MT | K35: Sim
B36: Os 3 métodos são sempre calculados e exibidos (transparência total). A escolha automática segue a convenção regional consolidada na literatura agronômica brasileira; o técnico responsável pode adotar outro método manualmente, se justificado pelas condições locais. | J36: MS | K36: Sim
J37: MG | K37: Não
J38: PA | K38: Sim
J39: PB | K39: Não
J40: PR | K40: Não
J41: PE | K41: Não
J42: PI | K42: Sim
...

Sheet Gessagem
B1: GESSAGEM — Necessidade de Gesso Agrícola
B3: 1. Parâmetros de entrada
B4: Teor de argila (%) | C4: ='Dados de Entrada'!C18
B5: Saturação por Alumínio m% - camada amostrada | C5: ='Dados de Entrada'!C46
B6: Cálcio (Ca²⁺, mmolc/dm³) - camada amostrada | C6: ='Dados de Entrada'!E28
B7: Cultura | C7: ='Dados de Entrada'!C8
B8: m% na camada 20-40 cm (opcional, se disponível)
B9: Ca²⁺ na camada 20-40 cm, mmolc/dm³ (opcional, se disponível)
B11: 2. Critério técnico de recomendação
B12: m% efetivo considerado | C12: =IF(C8="",C5,C8)
B13: Ca²⁺ efetivo considerado (mmolc/dm³) | C13: =IF(C9="",C6,C9)
B14: Camada usada no critério | C14: =IF(AND(C8="",C9=""),"Camada amostrada (aproximação)","20-40 cm (informada)")
B15: Recomenda-se gesso? | C15: =IF(OR(C12>20,C13<5),"Sim","Não")
B16: Critério atendido | C16: =IF(C15="Não","Nenhum critério de gessagem atendido",_xlfn.TEXTJOIN("; ",TRUE,IF(C12>20,"m% > 20%",""),IF(C13<5,"Ca²⁺ < 0,5 cmolc/dm³ (5 mmolc/dm³)","")))
B18: 3. Dose de gesso agrícola
B19: Cultura perene (fator 75) ou anual (fator 50)? | C19: =IF(OR(C7="Cana-de-açúcar",C7="Pastagem Panicum",C7="Pastagem Brachiaria"),"Perene (75)","Anual (50)")
B20: Dose de gesso agrícola (kg/ha) | C20: =IF(C15="Não",0,IF(C19="Perene (75)",75,50)*C4)
B21: Dose total para a área (t) | C21: =C20/1000*'Dados de Entrada'!C7
B22: Enxofre suprido pelo gesso (kg S/ha) | C22: =C20*0.15
B23: Cálcio suprido pelo gesso (kg Ca/ha) | C23: =C20*0.16
B24: Recomendação de parcelamento/logística | C24: =IF(C20=0,"Sem necessidade de gesso",IF(C20>2000,"Dose elevada - avaliar parcelamento em 2 aplicações e revisão técnica em campo","Aplicação única, a lanço, sem incorporação obrigatória"))
B26: 4. Fonte, confiança e limitações
B27: Fórmula e critério: Sousa, D.M.G.; Lobato, E. Uso de Gesso Agrícola nos Solos do Cerrado. Circular Técnica 32, Embrapa Cerrados, 2004/2005. Confiança: Alta (fórmula e critério qualitativo); Média (limiar exato de Ca subsuperficial, que varia entre 0,2-0,5 cmolc/dm³ conforme a fonte secundária consultada). Limitação: o valor de referência de 2.000 kg/ha acima não é um teto normativo confirmado na literatura consultada (não localizado em fonte primária) - trata-se de um alerta operacional prudente, não de uma regra agronômica rígida. Idealmente a avaliação usa amostra da camada 20-40 cm; nesta versão, a ausência dessa amostra é sinalizada e a camada disponível é usada como aproximação.

Sheet BD Culturas
B1: BANCO DE DADOS DE CULTURAS — Extração, Exportação e Curvas de Resposta
B3: Tabela editável. Soja e Milho possuem também extração total (não só exportação pelo grão), usada na aba de cada cultura para estimar o retorno de nutrientes via palhada/resíduo. Fonte e confiança por cultura na coluna Q/R.
B5: Cultura | C5: Unid. produtividade | D5: kg/unid. | E5: V% alvo | F5: Exp. N (kg/t) | G5: Exp. P2O5 (kg/t) | H5: Exp. K2O (kg/t) | I5: Exp. S (kg/t) | J5: Exp. Ca (kg/t) | K5: Exp. Mg (kg/t) | L5: Exp. B (kg/t) | M5: Exp. Zn (kg/t) | N5: Exp. Cu (kg/t) | O5: Exp. Mn (kg/t) | P5: Extr. N total (kg/t) | Q5: Extr. P2O5 total (kg/t) | R5: Extr. K2O total (kg/t) | S5: Fonte | T5: Confiança
B6: Soja | C6: sc/ha (60 kg) | D6: 60 | E6: 70 | F6: 50 | G6: 12 | H6: 20 | I6: 4 | J6: 3 | K6: 2.5 | L6: 0.02 | M6: 0.03 | N6: 0.008 | O6: 0.04 | P6: 80 | Q6: 16 | R6: 40 | S6: Sfredo, G.J. Soja no Brasil: calagem, adubação e nutrição mineral. Documentos 305, Embrapa Soja, 2008; valores consolidados também em Malavolta (2006) e boletins técnicos de manejo de fertilidade. | T6: Média (variação relevante relatada entre fontes, sobretudo para K em altas produtividades - efeito de diluição já discutido por Zanon et al. em curvas de resposta a potássio).
B7: Milho | C7: sc/ha (60 kg) | D7: 60 | E7: 70 | F7: 14 | G7: 7 | H7: 4.5 | I7: 1.5 | J7: 0.5 | K7: 1.2 | L7: 0.006 | M7: 0.015 | N7: 0.004 | O7: 0.025 | P7: 22 | Q7: 9 | R7: 20 | S7: Coelho, A.M. Nutrição e Adubação do Milho. Circular Técnica 78, Embrapa Milho e Sorgo, 2006 (valores 'clássicos' de exportação pelo grão). | T7: Média (circulares mais recentes revisam alguns coeficientes; verificar se tratam de grão isolado ou planta inteira/silagem antes de adotar valores diferentes).
B8: Sorgo | C8: sc/ha (60 kg) | D8: 60 | E8: 60 | F8: 18 | G8: 7 | H8: 6 | I8: 1.8 | J8: 0.6 | K8: 1.3 | L8: 0 | M8: 0 | N8: 0 | O8: 0 | S8: Valores de referência consolidados na prática agronômica (perfil nutricional próximo ao do milho, cultura de mesma família); ajustar com boletim regional (Embrapa Milho e Sorgo) quando disponível. | T8: Baixa-Média
B9: Feijão | C9: sc/ha (60 kg) | D9: 60 | E9: 70 | F9: 45 | G9: 12 | H9: 25 | I9: 3 | J9: 3 | K9: 3 | L9: 0 | M9: 0 | N9: 0 | O9: 0 | S9: Valores de referência consolidados na prática agronômica brasileira (perfil leguminosa, próximo à soja em proporção, porém com ciclo mais curto e menor fixação biológica líquida). Ajustar com boletim regional (IAC/Embrapa Arroz e Feijão) quando disponível. | T9: Baixa-Média
B10: Cana-de-açúcar | C10: t/ha | D10: 1000 | E10: 60 | F10: 1 | G10: 0.6 | H10: 1.7 | I10: 0.5 | J10: 0.5 | K10: 0.4 | L10: 0 | M10: 0 | N10: 0 | O10: 0 | S10: Valores de referência consolidados na prática agronômica (exportação por tonelada de colmo); ajustar com Boletim 200/Fundação MT ou boletim regional do setor sucroenergético quando disponível. | T10: Baixa-Média
B11: Pastagem Panicum | C11: t MS/ha | D11: 1000 | E11: 50 | F11: 15 | G11: 4 | H11: 18 | I11: 1.5 | J11: 3 | K11: 2 | L11: 0 | M11: 0 | N11: 0 | O11: 0 | S11: Valores de referência consolidados na prática agronômica para exportação por tonelada de matéria seca em pastagens tropicais (Panicum maximum); ajustar com boletim regional (Embrapa Gado de Corte) quando disponível. | T11: Baixa-Média
B12: Pastagem Brachiaria | C12: t MS/ha | D12: 1000 | E12: 50 | F12: 13 | G12: 3.5 | H12: 15 | I12: 1.3 | J12: 2.5 | K12: 1.8 | L12: 0 | M12: 0 | N12: 0 | O12: 0 | S12: Valores de referência consolidados na prática agronômica para exportação por tonelada de matéria seca em pastagens tropicais (Brachiaria/Urochloa spp.); ajustar com boletim regional (Embrapa Gado de Corte) quando disponível. | T12: Baixa-Média
B14: Fatores de eficiência de aproveitamento e ajuste por classe de fertilidade (modelo transparente)
B15: A recomendação de P e K desta planilha NÃO usa uma tabela fixa de doses. Ela calcula: dose de manutenção = (exportação pela produtividade meta) / (eficiência de aproveitamento do fertilizante, que depende da textura do solo) - e então aplica um fator de ajuste conforme a classe de fertilidade atual do solo (constrói fertilidade em solos pobres, reduz em solos já ricos). Isso integra análise de solo, textura, produtividade e exportação em vez de uma tabela estática. Os fatores abaixo são premissas explícitas e editáveis - não substituem curvas de resposta calibradas localmente.
B19: Textura | C19: Eficiência P (%) | D19: Eficiência K (%)
B20: Arenoso (< 15% argila) | C20: 0.35 | D20: 0.55
B21: Textura média (15-35% argila) | C21: 0.25 | D21: 0.65
B22: Argiloso (> 35% argila) | C22: 0.15 | D22: 0.75
B24: Classe de fertilidade | C24: Fator de ajuste P/K (construção-manutenção-redução)
B25: Muito baixo | C25: 2
B26: Baixo | C26: 1.5
B27: Médio | C27: 1.15
B28: Adequado | C28: 1
B29: Alto | C29: 0.7
B30: Muito alto | C30: 0.4
B32: Micronutriente | C32: Classe | D32: Dose sugerida via solo (kg/ha produto puro) | E32: Fonte/Confiança
A33: =B33&"|"&C33 | B33: Zn | C33: Baixo | D33: 4 | E33: Boletim 100 (síntese secundária) - Confiança Média
A34: =B34&"|"&C34 | B34: Zn | C34: Médio | D34: 2 | E34: Boletim 100 (síntese secundária) - Confiança Média
A35: =B35&"|"&C35 | B35: Zn | C35: Alto | D35: 0 | E35: Sem necessidade
A36: =B36&"|"&C36 | B36: B | C36: Baixo | D36: 1 | E36: Boletim 100 (síntese secundária) - Confiança Média
A37: =B37&"|"&C37 | B37: B | C37: Médio | D37: 0.5 | E37: Estimativa de uso corrente - Confiança Baixa
A38: =B38&"|"&C38 | B38: B | C38: Alto | D38: 0 | E38: Sem necessidade
A39: =B39&"|"&C39 | B39: Cu | C39: Baixo | D39: 2 | E39: Estimativa de uso corrente - Confiança Baixa
A40: =B40&"|"&C40 | B40: Cu | C40: Médio | D40: 1 | E40: Estimativa de uso corrente - Confiança Baixa
A41: =B41&"|"&C41 | B41: Cu | C41: Alto | D41: 0 | E41: Sem necessidade
A42: =B42&"|"&C42 | B42: Mn | C42: Baixo | D42: 3 | E42: Estimativa de uso corrente - Confiança Baixa (Mn frequentemente via foliar)
A43: =B43&"|"&C43 | B43: Mn | C43: Médio | D43: 1.5 | E43: Estimativa de uso corrente - Confiança Baixa
A44: =B44&"|"&C44 | B44: Mn | C44: Alto | D44: 0 | E44: Sem necessidade
... A47: =B47&"|"&C47 | B47: Mo | C47: Alto | D47: 0 | E47: Sem necessidade

Sheet Soja
B1: SOJA — Recomendação de Adubação (N-P-K-S-Micronutrientes)
B3: 1. Parâmetros de entrada
B4: Cultura selecionada em Dados de Entrada | C4: ='Dados de Entrada'!C8
B5: Alerta | C5: =IF(C4<>"Soja","A cultura em Dados de Entrada não é Soja - ajuste antes de usar esta aba","OK")
B6: Área (ha) | C6: ='Dados de Entrada'!C7
B7: Produtividade esperada | C7: ='Dados de Entrada'!C9
B8: Unidade | C8: ='Dados de Entrada'!C10
B9: Classe textural | C9: ='Dados de Entrada'!C19
B10: Matéria Orgânica (g/dm³) | C10: ='Dados de Entrada'!E25
B11: Sistema de plantio | C11: ='Dados de Entrada'!C12
B12: Produtividade meta em t/ha | C12: =C7*VLOOKUP("Soja",TAB_CULTURAS,3,FALSE)/1000
B14: 2. Classes de fertilidade (aba Interpretação)
B15: Classe - Fósforo | C15: =Interpretação!E6
B16: Classe - Potássio | C16: =Interpretação!E7
B17: Classe - Cálcio | C17: =Interpretação!E8
B18: Classe - Magnésio | C18: =Interpretação!E9
B19: Classe - Enxofre | C19: =Interpretação!E12
B20: Classe - Zinco | C20: =Interpretação!E13
B21: Classe - Boro | C21: =Interpretação!E17
B22: Classe - Cobre | C22: =Interpretação!E14
B23: Classe - Manganês | C23: =Interpretação!E15
B24: Classe - Molibdênio | C24: =Interpretação!E18
B26: 3. Nitrogênio
B27: Inoculação com Bradyrhizobium realizada corretamente? | C27: Sim
B28: Nitrogênio recomendado (kg N/ha) | C28: =IF(C27="Sim",0,C12*VLOOKUP("Soja",TAB_CULTURAS,5,FALSE)/0.5)
B29: Fonte/Confiança: Alta - Embrapa Soja (doutrina consolidada): soja bem inoculada com Bradyrhizobium não responde economicamente à adubação nitrogenada mineral, mesmo em altas produtividades, pois a fixação biológica supre a demanda. Se a inoculação não for confirmada, calcula-se uma dose plena por exportação/eficiência (fórmula igual à do milho) como contingência.
B33: 4. Fósforo (P2O5)
B34: Exportação pela produtividade meta (kg/ha) | C34: =C12*VLOOKUP("Soja",TAB_CULTURAS,6,FALSE)
B35: Eficiência de aproveitamento do fertilizante (%) | C35: =VLOOKUP(C9,TAB_EFICIENCIA,2,FALSE)
B36: Dose de manutenção (exportação / eficiência), kg/ha | C36: =C34/C35
B37: Classe de fertilidade considerada | C37: =C15
B38: Fator de ajuste por classe (construção/manutenção/redução) | C38: =VLOOKUP(C15,TAB_FATOR_CLASSE,2,FALSE)
B39: Dose final de P2O5 (kg/ha) | C39: =C36*C38
B40: Total para a área (kg) | C40: =C39*C6
B41: Modelo: dose = (exportação pelo grão na produtividade meta / eficiência de aproveitamento pela textura) x fator de ajuste pela classe de fertilidade atual do solo. Não é uma tabela fixa - recalcula a cada mudança de solo, textura ou produtividade. Fonte dos coeficientes de exportação: ver aba BD Culturas. Confiança do fator de ajuste: Média (premissa transparente e editável).
B45: 5. Potássio (K2O)
B46: Exportação pela produtividade meta (kg/ha) | C46: =C12*VLOOKUP("Soja",TAB_CULTURAS,7,FALSE)
B47: Eficiência de aproveitamento do fertilizante (%) | C47: =VLOOKUP(C9,TAB_EFICIENCIA,3,FALSE)
B48: Dose de manutenção (exportação / eficiência), kg/ha | C48: =C46/C47
B49: Classe de fertilidade considerada | C49: =C16
...

Sheet Milho
B1: MILHO — Recomendação de Adubação (N-P-K-S-Micronutrientes)
B3: 1. Parâmetros de entrada
B4: Cultura selecionada em Dados de Entrada | C4: ='Dados de Entrada'!C8
B5: Alerta | C5: =IF(C4<>"Milho","A cultura em Dados de Entrada não é Milho - ajuste antes de usar esta aba","OK")
B6: Área (ha) | C6: ='Dados de Entrada'!C7
B7: Produtividade esperada | C7: ='Dados de Entrada'!C9
B8: Unidade | C8: ='Dados de Entrada'!C10
B9: Classe textural | C9: ='Dados de Entrada'!C19
B10: Matéria Orgânica (g/dm³) | C10: ='Dados de Entrada'!E25
B11: Sistema de plantio | C11: ='Dados de Entrada'!C12
B12: Produtividade meta em t/ha | C12: =C7*VLOOKUP("Milho",TAB_CULTURAS,3,FALSE)/1000
B14: 2. Classes de fertilidade (aba Interpretação)
B15: Classe - Fósforo | C15: =Interpretação!E6
B16: Classe - Potássio | C16: =Interpretação!E7
B17: Classe - Cálcio | C17: =Interpretação!E8
B18: Classe - Magnésio | C18: =Interpretação!E9
B19: Classe - Enxofre | C19: =Interpretação!E12
B20: Classe - Zinco | C20: =Interpretação!E13
B21: Classe - Boro | C21: =Interpretação!E17
B22: Classe - Cobre | C22: =Interpretação!E14
B23: Classe - Manganês | C23: =Interpretação!E15
B24: Classe - Molibdênio | C24: =Interpretação!E18
B26: 3. Nitrogênio
B27: Cultura anterior foi leguminosa (crédito de N)? | C27: Não
B28: Eficiência de aproveitamento do N (%) | C28: 0.6
B29: Exportação de N pela produtividade meta (kg/ha) | C29: =C12*VLOOKUP("Milho",TAB_CULTURAS,5,FALSE)
B30: Nitrogênio recomendado (kg N/ha) | C30: =MAX(0,C29/C28-IF(C27="Sim",25,0))
B31: Fonte/Confiança: Média - dose de manutenção por exportação/eficiência, com crédito de N de 25 kg/ha quando a cultura anterior foi leguminosa bem nodulada (estimativa de uso corrente). Não substitui curva de resposta a N calibrada localmente (solo, clima, híbrido).
B35: 4. Fósforo (P2O5)
B36: Exportação pela produtividade meta (kg/ha) | C36: =C12*VLOOKUP("Milho",TAB_CULTURAS,6,FALSE)
B37: Eficiência de aproveitamento do fertilizante (%) | C37: =VLOOKUP(C9,TAB_EFICIENCIA,2,FALSE)
B38: Dose de manutenção (exportação / eficiência), kg/ha | C38: =C36/C37
B39: Classe de fertilidade considerada | C39: =C15
B40: Fator de ajuste por classe (construção/manutenção/redução) | C40: =VLOOKUP(C15,TAB_FATOR_CLASSE,2,FALSE)
B41: Dose final de P2O5 (kg/ha) | C41: =C38*C40
B42: Total para a área (kg) | C42: =C41*C6
B43: Modelo: dose = (exportação pelo grão na produtividade meta / eficiência de aproveitamento pela textura) x fator de ajuste pela classe de fertilidade atual do solo. Não é uma tabela fixa - recalcula a cada mudança de solo, textura ou produtividade. Fonte dos coeficientes de exportação: ver aba BD Culturas. Confiança do fator de ajuste: Média (premissa transparente e editável).
B47: 5. Potássio (K2O)
B48: Exportação pela produtividade meta (kg/ha) | C48: =C12*VLOOKUP("Milho",TAB_CULTURAS,7,FALSE)
B49: Eficiência de aproveitamento do fertilizante (%) | C49: =VLOOKUP(C9,TAB_EFICIENCIA,3,FALSE)
...

Sheet Outras Culturas
B1: OUTRAS CULTURAS — Sorgo, Feijão, Cana-de-açúcar, Panicum e Brachiaria (nível de manutenção/reposição)
B3: Módulo simplificado (Fase 1): calcula a adubação de manutenção pela exportação de nutrientes na produtividade meta, ajustada pela eficiência de aproveitamento (textura do solo) - sem o fator de ajuste fino por classe de fertilidade usado em Soja/Milho e sem curva de resposta específica. Use como referência inicial; para essas culturas recomenda-se complementar com boletim regional (Embrapa Milho e Sorgo, Embrapa Arroz e Feijão, Fundação MT/Boletim 200, Embrapa Gado de Corte) conforme a cultura selecionada.
B7: 1. Parâmetros de entrada
B8: Cultura selecionada em Dados de Entrada | C8: ='Dados de Entrada'!C8
B9: Alerta | C9: =IF(OR(C8="Soja",C8="Milho"),"Soja e Milho têm abas dedicadas com motor completo - use-as no lugar desta",IF(OR(C8="Sorgo",C8="Feijão",C8="Cana-de-açúcar",C8="Pastagem Panicum",C8="Pastagem Brachiaria"),"OK","Cultura não reconhecida"))
B10: Área (ha) | C10: ='Dados de Entrada'!C7
B11: Produtividade esperada | C11: ='Dados de Entrada'!C9
B12: Unidade | C12: ='Dados de Entrada'!C10
B13: Classe textural | C13: ='Dados de Entrada'!C19
B14: Produtividade meta convertida (t/ha ou t MS/ha) | C14: =C11*VLOOKUP(C8,TAB_CULTURAS,3,FALSE)/1000
B16: 2. Eficiência de aproveitamento adotada
B17: Eficiência P (%) - conforme textura | C17: =VLOOKUP(C13,TAB_EFICIENCIA,2,FALSE)
B18: Eficiência K (%) - conforme textura | C18: =VLOOKUP(C13,TAB_EFICIENCIA,3,FALSE)
B19: Eficiência N e S (%) - padrão geral | C19: 0.55
B21: 3. Adubação de manutenção recomendada (exportação / eficiência)
B22: Nutriente | C22: Exportação (kg/ha) | D22: Dose recomendada (kg/ha) | E22: Total área (kg)
B23: N | C23: =C14*VLOOKUP(C8,TAB_CULTURAS,5,FALSE) | D23: =C23/C19 | E23: =D23*C10
B24: P2O5 | C24: =C14*VLOOKUP(C8,TAB_CULTURAS,6,FALSE) | D24: =C24/C17 | E24: =D24*C10
B25: K2O | C25: =C14*VLOOKUP(C8,TAB_CULTURAS,7,FALSE) | D25: =C25/C18 | E25: =D25*C10
B26: S | C26: =C14*VLOOKUP(C8,TAB_CULTURAS,8,FALSE) | D26: =C26/C19 | E26: =D26*C10
B27: Ca (informativo) | C27: =C14*VLOOKUP(C8,TAB_CULTURAS,9,FALSE) | D27: Ver Calagem/Gessagem
B28: Mg (informativo) | C28: =C14*VLOOKUP(C8,TAB_CULTURAS,10,FALSE) | D28: Ver Calagem/Gessagem
B30: Fonte dos coeficientes de exportação: ver aba BD Culturas (coluna Fonte/Confiança por cultura). Confiança geral deste módulo simplificado: Baixa-Média - adequado como estimativa inicial de manutenção, não substitui curva de resposta local nem tabela oficial por classe de solo específica da cultura.

Sheet BD Fertilizantes
B1: BANCO DE DADOS DE FERTILIZANTES — Composição Garantida e Preço de Referência
B3: Tabela editável. Ajuste os percentuais conforme o rótulo/garantia do produto realmente utilizado e o preço de referência (R$/t) conforme cotação local. Linhas em branco no final permitem adicionar novos produtos - basta preencher Nome e os percentuais de garantia; a aba Mistura de Fertilizantes referencia esta tabela por nome de produto.
B5: Produto | C5: N (%) | D5: P2O5 (%) | E5: K2O (%) | F5: S (%) | G5: Ca (%) | H5: Mg (%) | I5: CaO (%) | J5: MgO (%) | K5: PRNT (%) | L5: B (%) | M5: Zn (%) | N5: Cu (%) | O5: Mn (%) | P5: Mo (%) | Q5: Preço ref. (R$/t)
B6: Ureia | C6: 45 | D6: 0 | E6: 0 | F6: 0 | G6: 0 | H6: 0 | I6: 0 | J6: 0 | K6: 0 | L6: 0 | M6: 0 | N6: 0 | O6: 0 | P6: 0 | Q6: 2600
B7: Sulfato de Amônio | C7: 20 | D7: 0 | E7: 0 | F7: 24 | G7: 0 | H7: 0 | I7: 0 | J7: 0 | K7: 0 | L7: 0 | M7: 0 | N7: 0 | O7: 0 | P7: 0 | Q7: 2100
B8: Nitrato de Amônio | C8: 32 | D8: 0 | E8: 0 | F8: 0 | G8: 0 | H8: 0 | I8: 0 | J8: 0 | K8: 0 | L8: 0 | M8: 0 | N8: 0 | O8: 0 | P8: 0 | Q8: 2700
B9: MAP (11-52-00) | C9: 11 | D9: 52 | E9: 0 | F9: 0 | G9: 0 | H9: 0 | I9: 0 | J9: 0 | K9: 0 | L9: 0 | M9: 0 | N9: 0 | O9: 0 | P9: 0 | Q9: 4200
B10: DAP (18-46-00) | C10: 18 | D10: 46 | E10: 0 | F10: 0 | G10: 0 | H10: 0 | I10: 0 | J10: 0 | K10: 0 | L10: 0 | M10: 0 | N10: 0 | O10: 0 | P10: 0 | Q10: 4100
B11: Superfosfato Simples | C11: 0 | D11: 18 | E11: 0 | F11: 10 | G11: 18 | H11: 0 | I11: 0 | J11: 0 | K11: 0 | L11: 0 | M11: 0 | N11: 0 | O11: 0 | P11: 0 | Q11: 2000
B12: Superfosfato Triplo | C12: 0 | D12: 41 | E12: 0 | F12: 0 | G12: 12 | H12: 0 | I12: 0 | J12: 0 | K12: 0 | L12: 0 | M12: 0 | N12: 0 | O12: 0 | P12: 0 | Q12: 3600
B13: Termofosfato (Yoorin) | C13: 0 | D13: 17 | E13: 0 | F13: 0 | G13: 18 | H13: 6 | I13: 0 | J13: 0 | K13: 0 | L13: 0.1 | M13: 0.4 | N13: 0 | O13: 0 | P13: 0 | Q13: 2400
B14: Fosfato Natural Reativo | C14: 0 | D14: 28 | E14: 0 | F14: 0 | G14: 30 | H14: 0 | I14: 0 | J14: 0 | K14: 0 | L14: 0 | M14: 0 | N14: 0 | O14: 0 | P14: 0 | Q14: 2200
B15: Cloreto de Potássio | C15: 0 | D15: 0 | E15: 58 | F15: 0 | G15: 0 | H15: 0 | I15: 0 | J15: 0 | K15: 0 | L15: 0 | M15: 0 | N15: 0 | O15: 0 | P15: 0 | Q15: 3600
B16: Sulfato de Potássio | C16: 0 | D16: 0 | E16: 50 | F16: 17 | G16: 0 | H16: 0 | I16: 0 | J16: 0 | K16: 0 | L16: 0 | M16: 0 | N16: 0 | O16: 0 | P16: 0 | Q16: 5200
B17: Nitrato de Potássio | C17: 13 | D17: 0 | E17: 44 | F17: 0 | G17: 0 | H17: 0 | I17: 0 | J17: 0 | K17: 0 | L17: 0 | M17: 0 | N17: 0 | O17: 0 | P17: 0 | Q17: 6800
... B28: Organomineral 04-14-08 | C28: 4 | D28: 14 | E28: 8 | F28: 0 | G28: 0 | H28: 0 | I28: 0 | J28: 0 | K28: 0 | L28: 0 | M28: 0 | N28: 0 | O28: 0 | P28: 0 | Q28: 1800
C29: 0 | D29: 0 | E29: 0 | F29: 0 | G29: 0 | H29: 0 | I29: 0 | J29: 0 | K29: 0 | L29: 0 | M29: 0 | N29: 0 | O29: 0 | P29: 0 | Q29: 0
C30: 0 | D30: 0 | E30: 0 | F30: 0 | G30: 0 | H30: 0 | I30: 0 | J30: 0 | K30: 0 | L30: 0 | M30: 0 | N30: 0 | O30: 0 | P30: 0 | Q30: 0
C31: 0 | D31: 0 | E31: 0 | F31: 0 | G31: 0 | H31: 0 | I31: 0 | J31: 0 | K31: 0 | L31: 0 | M31: 0 | N31: 0 | O31: 0 | P31: 0 | Q31: 0
C32: 0 | D32: 0 | E32: 0 | F32: 0 | G32: 0 | H32: 0 | I32: 0 | J32: 0 | K32: 0 | L32: 0 | M32: 0 | N32: 0 | O32: 0 | P32: 0 | Q32: 0
C33: 0 | D33: 0 | E33: 0 | F33: 0 | G33: 0 | H33: 0 | I33: 0 | J33: 0 | K33: 0 | L33: 0 | M33: 0 | N33: 0 | O33: 0 | P33: 0 | Q33: 0
C34: 0 | D34: 0 | E34: 0 | F34: 0 | G34: 0 | H34: 0 | I34: 0 | J34: 0 | K34: 0 | L34: 0 | M34: 0 | N34: 0 | O34: 0 | P34: 0 | Q34: 0
C35: 0 | D35: 0 | E35: 0 | F35: 0 | G35: 0 | H35: 0 | I35: 0 | J35: 0 | K35: 0 | L35: 0 | M35: 0 | N35: 0 | O35: 0 | P35: 0 | Q35: 0
C36: 0 | D36: 0 | E36: 0 | F36: 0 | G36: 0 | H36: 0 | I36: 0 | J36: 0 | K36: 0 | L36: 0 | M36: 0 | N36: 0 | O36: 0 | P36: 0 | Q36: 0

Sheet Mistura de Fertilizantes
B1: MISTURA DE FERTILIZANTES — Produtos, Doses e Custo Estimado
B3: Metodologia de seleção: heurística de regras transparentes (não é um solver de otimização por programação linear) - prioriza menor número de produtos e aproveitamento cruzado de nutrientes (ex.: fonte de P que já traz enxofre evita precisar de sulfato de amônio). Todas as escolhas e doses são auditáveis nas fórmulas. Para otimização de custo mínimo real entre múltiplas fontes concorrentes, uma fase futura com Solver/VBA pode ser adicionada - ver Manual Técnico, seção Limitações.
B7: 1. Necessidade de nutrientes (puxada automaticamente da cultura selecionada)
B8: Nutriente | C8: Necessidade (kg/ha)
B9: N | C9: =IF('Dados de Entrada'!C8="Soja",Soja!C78,IF('Dados de Entrada'!C8="Milho",Milho!C80,'Outras Culturas'!D23))
B10: P2O5 | C10: =IF('Dados de Entrada'!C8="Soja",Soja!C79,IF('Dados de Entrada'!C8="Milho",Milho!C81,'Outras Culturas'!D24))
B11: K2O | C11: =IF('Dados de Entrada'!C8="Soja",Soja!C80,IF('Dados de Entrada'!C8="Milho",Milho!C82,'Outras Culturas'!D25))
B12: S | C12: =IF('Dados de Entrada'!C8="Soja",Soja!C81,IF('Dados de Entrada'!C8="Milho",Milho!C83,'Outras Culturas'!D26))
B13: Zn | C13: =IF('Dados de Entrada'!C8="Soja",Soja!C82,IF('Dados de Entrada'!C8="Milho",Milho!C84,0))
B14: B | C14: =IF('Dados de Entrada'!C8="Soja",Soja!C83,IF('Dados de Entrada'!C8="Milho",Milho!C85,0))
B15: Cu | C15: =IF('Dados de Entrada'!C8="Soja",Soja!C84,IF('Dados de Entrada'!C8="Milho",Milho!C86,0))
B16: Mn | C16: =IF('Dados de Entrada'!C8="Soja",Soja!C85,IF('Dados de Entrada'!C8="Milho",Milho!C87,0))
B17: Mo | C17: =IF('Dados de Entrada'!C8="Soja",Soja!C86,IF('Dados de Entrada'!C8="Milho",Milho!C88,0))
B19: 2. Seleção de fontes (heurística)
B20: Fonte de P2O5 escolhida | C20: =IF(C12>0,"Superfosfato Simples","MAP (11-52-00)")
B21: Fonte de K2O escolhida | C21: =IF(Interpretação!E9="Baixo","K-Mag (Sulpomag)","Cloreto de Potássio")
B22: Fonte de N escolhida | C22: =IF(C20="Superfosfato Simples","Ureia",IF(C12>0,"Sulfato de Amônio","Ureia"))
B23: Fonte de micronutrientes escolhida | C23: =IF(OR(C13>0,C14>0,C15>0,C16>0,C17>0),"FTE BR-12","-")
B25: 3. Doses de produto e custo
B26: Produto | C26: Nutriente-alvo | D26: Dose (kg/ha) | E26: Total área (kg) | F26: Preço (R$/t) | G26: Custo (R$/ha)
B27: =C22 | C27: N | D27: =IF(B27="-",0,IFERROR(C9/(VLOOKUP(B27,TAB_FERT,2,FALSE)/100),0)) | E27: =D27*'Dados de Entrada'!C7 | F27: =IF(B27="-",0,IFERROR(VLOOKUP(B27,TAB_FERT,16,FALSE),0)) | G27: =D27*F27/1000
B28: =C20 | C28: P2O5 | D28: =IF(B28="-",0,IFERROR(C10/(VLOOKUP(B28,TAB_FERT,3,FALSE)/100),0)) | E28: =D28*'Dados de Entrada'!C7 | F28: =IF(B28="-",0,IFERROR(VLOOKUP(B28,TAB_FERT,16,FALSE),0)) | G28: =D28*F28/1000
B29: =C21 | C29: K2O | D29: =IF(B29="-",0,IFERROR(C11/(VLOOKUP(B29,TAB_FERT,4,FALSE)/100),0)) | E29: =D29*'Dados de Entrada'!C7 | F29: =IF(B29="-",0,IFERROR(VLOOKUP(B29,TAB_FERT,16,FALSE),0)) | G29: =D29*F29/1000
B30: =C23 | C30: Zn/B/Cu/Mn/Mo (limitante) | D30: =IF(B30="-",0,IFERROR(MAX(C13/9,C14/1.8,C15/0.8,C16/2,C17/0.1)*9/(VLOOKUP(B30,TAB_FERT,12,FALSE)/100),0)) | E30: =D30*'Dados de Entrada'!C7 | F30: =IF(B30="-",0,IFERROR(VLOOKUP(B30,TAB_FERT,16,FALSE),0)) | G30: =D30*F30/1000
B32: 4. Balanço de Enxofre (informativo)
B33: S necessário pela cultura (kg/ha) | C33: =C12
B34: S suprido pela fonte de N escolhida (kg/ha) | C34: =D27*VLOOKUP(B27,TAB_FERT,5,FALSE)/100
B35: S suprido pela fonte de P escolhida (kg/ha) | C35: =D28*VLOOKUP(B28,TAB_FERT,5,FALSE)/100
B36: S suprido pelo gesso agrícola recomendado (kg/ha) | C36: =Gessagem!C22
B37: Saldo de S (necessário - suprido) | C37: =C12-C34-C35-C36
B38: Se o saldo for positivo (faltando S), considere substituir a fonte de K por Sulfato de Potássio ou adicionar gesso/sulfato adicional.
B40: 5. Resumo de Custo
B41: Número de produtos utilizados | C41: =SUMPRODUCT(--(D27:D30>0))
B42: Custo total de fertilizantes (R$/ha) | C42: =SUM(G27:G30)
B43: Custo total de calcário (R$/ha) | C43: =Calagem!C27*VLOOKUP("Calcário Dolomítico (PRNT 90%)",TAB_FERT,16,FALSE)
B44: Custo total de gesso (R$/ha) | C44: =Gessagem!C20/1000*VLOOKUP("Gesso Agrícola",TAB_FERT,16,FALSE)
B45: CUSTO TOTAL DE CORREÇÃO + ADUBAÇÃO (R$/ha) | C45: =C42+C43+C44
B46: CUSTO TOTAL PARA A ÁREA (R$) | C46: =C45*'Dados de Entrada'!C7

Sheet Resumo
B1: RESUMO — Diagnóstico, Balanço Nutricional e Custo
B3: 1. Identificação
B4: Fazenda/Talhão | C4: ='Dados de Entrada'!C4
B5: Município/UF | C5: ='Dados de Entrada'!C5
B6: Cultura | C6: ='Dados de Entrada'!C8
B7: Área (ha) | C7: ='Dados de Entrada'!C7
B8: Produtividade meta | C8: ='Dados de Entrada'!C9
B10: 2. Diagnóstico do Solo
B11: Limitações identificadas (Muito baixo/Baixo, ou m% Alto) | C11: =Interpretação!B22
B14: 3. Correção do Solo
B15: Método de calagem recomendado | C15: =Calagem!C26
B16: Calcário - dose final (t/ha) | C16: =Calagem!C27
B17: Calcário - total área (t) | C17: =Calagem!C28
B18: Gesso - recomendado? | C18: =Gessagem!C15
B19: Gesso - dose (kg/ha) | C19: =Gessagem!C20
B21: 4. Balanço Nutricional (kg/ha)
B22: Nutriente | C22: Necessidade (kg/ha) | D22: Classe do solo | E22: Score (1-6)
B23: N | C23: ='Mistura de Fertilizantes'!C9 | D23: -
B24: P2O5 | C24: ='Mistura de Fertilizantes'!C10 | D24: =Interpretação!E6 | E24: =IF(D24="Muito baixo",1,IF(D24="Baixo",2,IF(D24="Médio",3,IF(D24="Adequado",4,IF(D24="Alto",5,IF(D24="Muito alto",6,""))))))
B25: K2O | C25: ='Mistura de Fertilizantes'!C11 | D25: =Interpretação!E7 | E25: =IF(D25="Muito baixo",1,IF(D25="Baixo",2,IF(D25="Médio",3,IF(D25="Adequado",4,IF(D25="Alto",5,IF(D25="Muito alto",6,""))))))
B26: S | C26: ='Mistura de Fertilizantes'!C12 | D26: =Interpretação!E12 | E26: =IF(D26="Muito baixo",1,IF(D26="Baixo",2,IF(D26="Médio",3,IF(D26="Adequado",4,IF(D26="Alto",5,IF(D26="Muito alto",6,""))))))
B27: Zn | C27: ='Mistura de Fertilizantes'!C13 | D27: =Interpretação!E13 | E27: =IF(D27="Muito baixo",1,IF(D27="Baixo",2,IF(D27="Médio",3,IF(D27="Adequado",4,IF(D27="Alto",5,IF(D27="Muito alto",6,""))))))
B28: B | C28: ='Mistura de Fertilizantes'!C14 | D28: =Interpretação!E17 | E28: =IF(D28="Muito baixo",1,IF(D28="Baixo",2,IF(D28="Médio",3,IF(D28="Adequado",4,IF(D28="Alto",5,IF(D28="Muito alto",6,""))))))
B29: Cu | C29: ='Mistura de Fertilizantes'!C15 | D29: =Interpretação!E14 | E29: =IF(D29="Muito baixo",1,IF(D29="Baixo",2,IF(D29="Médio",3,IF(D29="Adequado",4,IF(D29="Alto",5,IF(D29="Muito alto",6,""))))))
B30: Mn | C30: ='Mistura de Fertilizantes'!C16 | D30: =Interpretação!E15 | E30: =IF(D30="Muito baixo",1,IF(D30="Baixo",2,IF(D30="Médio",3,IF(D30="Adequado",4,IF(D30="Alto",5,IF(D30="Muito alto",6,""))))))
B31: Mo | C31: ='Mistura de Fertilizantes'!C17 | D31: =Interpretação!E18 | E31: =IF(D31="Muito baixo",1,IF(D31="Baixo",2,IF(D31="Médio",3,IF(D31="Adequado",4,IF(D31="Alto",5,IF(D31="Muito alto",6,""))))))
B33: 5. Custo
B34: Custo de correção + adubação (R$/ha) | C34: ='Mistura de Fertilizantes'!C45
B35: Custo total para a área (R$) | C35: ='Mistura de Fertilizantes'!C46
B38: 6. Gráficos

Sheet Referências
B1: REFERÊNCIAS BIBLIOGRÁFICAS
B3: RAIJ, B. van; CANTARELLA, H.; QUAGGIO, J.A.; FURLANI, A.M.C. (Eds.). Recomendações de Adubação e Calagem para o Estado de São Paulo. Boletim Técnico 100, 2ª ed. Campinas: Instituto Agronômico (IAC), 1997.
B4: SOUSA, D.M.G. de; LOBATO, E. (Eds.). Cerrado: Correção do Solo e Adubação. 2ª ed. Brasília: Embrapa Informação Tecnológica / Embrapa Cerrados, 2004.
B5: SOUSA, D.M.G. de; LOBATO, E. Uso de Gesso Agrícola nos Solos do Cerrado. Circular Técnica 32. Planaltina: Embrapa Cerrados, 2004.
B6: KAMPRATH, E.J. Exchangeable aluminum as a criterion for liming leached mineral soils. Soil Science Society of America Proceedings, v.34, p.252-254, 1970.
B7: SFREDO, G.J. Soja no Brasil: calagem, adubação e nutrição mineral. Documentos 305. Londrina: Embrapa Soja, 2008.
B8: COELHO, A.M. Nutrição e Adubação do Milho. Circular Técnica 78. Sete Lagoas: Embrapa Milho e Sorgo, 2006.
B9: MALAVOLTA, E. Manual de Nutrição Mineral de Plantas. São Paulo: Editora Agronômica Ceres, 2006.
B10: SOCIEDADE BRASILEIRA DE CIÊNCIA DO SOLO (SBCS). Manual de Calagem e Adubação para os Estados do Rio Grande do Sul e de Santa Catarina. Comissão de Química e Fertilidade do Solo - RS/SC, 11ª ed., 2016.
B11: ALVAREZ V., V.H.; RIBEIRO, A.C. Calagem. In: RIBEIRO, A.C.; GUIMARÃES, P.T.G.; ALVAREZ V., V.H. (Eds.) Recomendações para o uso de corretivos e fertilizantes em Minas Gerais - 5ª Aproximação. Viçosa: CFSEMG, 1999.
B12: FUNDAÇÃO MT. Boletim de Pesquisa de Soja / Boletim 200 (referência institucional - valores numéricos específicos não confirmados nesta versão; consultar publicação atualizada da Fundação MT).
B13: FAGERIA, N.K.; BALIGAR, V.C. Ameliorating soil acidity of tropical Oxisols by liming for sustainable crop production. Advances in Agronomy, v.99, 2008.
... B18: AGRADECIMENTOS/AVISO: parte da compilação desta planilha envolveu pesquisa bibliográfica assistida por IA em fontes secundárias (motores de busca) quando o texto integral das obras primárias não pôde ser acessado diretamente. Onde isso ocorreu, o nível de confiança foi rebaixado e sinalizado explicitamente no Manual Técnico e nas respectivas abas - recomenda-se validação contra o documento original antes de uso comercial.
